<?xml version="1.0" ?>
<robot name="calibration_xform" xmlns:xacro="http://ros.org/wiki/xacro">
  <xacro:macro name="calibration_definitions" params="child_link parent_link">
    <link name="${child_link}_x_trans">
      <visual>
        <origin rpy="0 0 0" xyz="0 0 0"/>
        <geometry>
          <sphere radius="0.0005"/>
        </geometry>
      </visual>
    </link>
    <link name="${child_link}_y_trans"/>
    <link name="${child_link}_z_trans"/>
    <link name="${child_link}_pitch"/>
    <link name="${child_link}_yaw"/>

    <joint name="${child_link}_x_joint" type="prismatic">
      <parent link="${parent_link}"/>
      <child  link="${child_link}_x_trans"/>
      <origin xyz="0 0 0" rpy="0 0 0"/>
      <axis xyz="1 0 0" rpy="0 0 0"/>
      <limit lower="-1.0" upper="1.0" effort="30" velocity="0.0508"/>
    </joint>

    <joint name="${child_link}_y_joint" type="prismatic">
      <parent link="${child_link}_x_trans"/>
      <child  link="${child_link}_y_trans"/>
      <origin xyz="0 0 0" rpy="0 0 0"/>
      <axis xyz="0 1 0" rpy="0 0 0"/>
      <limit lower="-1.0" upper="1.0" effort="30" velocity="0.0508"/>
    </joint>

    <joint name="${child_link}_z_joint" type="prismatic">
      <parent link="${child_link}_y_trans"/>
      <child  link="${child_link}_z_trans"/>
      <origin xyz="0 0 0" rpy="0 0 0"/>
      <axis xyz="0 0 1" rpy="0 0 0"/>
      <limit lower="-1.0" upper="1.0" effort="30" velocity="0.0508"/>
    </joint>

    <joint name="${child_link}_yaw_joint" type="revolute">
      <parent link="${child_link}_z_trans"/>
      <child  link="${child_link}_yaw"/>
      <origin xyz="0 0 0" rpy="0 0 0"/>
      <limit lower="-6.2832" upper="6.2832" effort="2" velocity="10"/>
      <axis xyz="0 0 1"/>
    </joint>

    <joint name="${child_link}_pitch_joint" type="revolute">
      <parent link="${child_link}_yaw"/>
      <child  link="${child_link}_pitch"/>
      <origin xyz="0 0 0" rpy="0 0 0"/>
      <limit lower="-6.2832" upper="6.2832" effort="2" velocity="10"/>
      <axis xyz="0 1 0"/>
    </joint>

    <joint name="${child_link}_roll_joint" type="revolute">
      <parent link="${child_link}_pitch"/>
      <child  link="${child_link}"/>
      <origin xyz="0 0 0" rpy="0 0 0"/>
      <limit lower="-6.2832" upper="6.2832" effort="2" velocity="10"/>
      <axis xyz="1 0 0"/>
    </joint>

  </xacro:macro>
</robot>
